<?xml version ="1.0"?>
<robot name ="2r_planar">
    <material name="blue">
        <color rgba="0 0 0.8 1"/>
    </material>

    <material name="white">
        <color rgba="1 1 1 1"/>
    </material>

    <link name ="base_link">
        <visual>
            <geometry>
                <box size="0.1 0.1 0.1"/>
            </geometry>
        </visual>
    </link>
    <link name="link_1">
        <visual>
            <origin xyz="0 0 0.5"/>
            <geometry>
                <cylinder length="1" radius="0.01"/>
            </geometry>
            <material name="blue"/>
        </visual>
        <inertial>
            <mass value="12.456"/>
            <inertia ixx="0.0" ixy="0.0" ixz="0.0" iyy="0.0" iyz="0.0" izz="1.042"/>
        </inertial>
    </link>
    <link name="link_2">
        <visual>
            <origin xyz="0 0 0.5"/>
            <geometry>
                <cylinder length="1" radius="0.01"/>
            </geometry>
        <material name="blue"/>
        </visual>
        <inertial>
            <mass value="12.456"/>
            <inertia ixx="0.0" ixy="0.0" ixz="0.0" iyy="0.0" iyz="0.0" izz="1.042"/>
        </inertial>
    </link>

    <joint name="joint_1" type="revolute">
        <axis xyz="1 0 0"/>
        <origin rpy="0 0 0"  xyz="0.055 0 0"/>
        <limit effort="1000.0" lower="0.0" upper="3.14" velocity="0.5"/>
        <parent link="base_link"/>
        <child link="link_1"/>
    </joint> 

    <joint name="joint_2" type="revolute">
        <axis xyz="1 0 0"/>
        <origin rpy="0 0 0"  xyz="-0.02 0 1"/>
        <limit effort="1000.0" lower="0.0" upper="3.14" velocity="0.5"/>
        <parent link="link_1"/>
        <child link="link_2"/>
    </joint>   
</robot>
